Task was destroyed but it is pending!
task: <Task pending name='Task-60' coro=<Event.wait() done, defined at /usr/local/lib/python3.9/asyncio/locks.py:213> wait_for=<Future pending cb=[<TaskWakeupMethWrapper object at 0xb3e2c028>()]>>
I'm on ready...
<<<<<<< HEAD
2021-12-01 15:18:53.654760: W tensorflow/stream_executor/platform/default/dso_loader.cc:64] Could not load dynamic library 'libcudart.so.11.0'; dlerror: libcudart.so.11.0: cannot open shared object file: No such file or directory
2021-12-01 15:18:53.654807: I tensorflow/stream_executor/cuda/cudart_stub.cc:29] Ignore above cudart dlerror if you do not have a GPU set up on your machine.
 * Serving Flask app 'AIReplyAPI' (lazy loading)
 * Environment: production
   WARNING: This is a development server. Do not use it in a production deployment.
   Use a production WSGI server instead.
 * Debug mode: on
 * Running on all addresses.
   WARNING: This is a development server. Do not use it in a production deployment.
 * Running on http://10.40.3.171:51401/ (Press CTRL+C to quit)
 * Restarting with stat
2021-12-01 15:18:56.480833: W tensorflow/stream_executor/platform/default/dso_loader.cc:64] Could not load dynamic library 'libcudart.so.11.0'; dlerror: libcudart.so.11.0: cannot open shared object file: No such file or directory
2021-12-01 15:18:56.480878: I tensorflow/stream_executor/cuda/cudart_stub.cc:29] Ignore above cudart dlerror if you do not have a GPU set up on your machine.
 * Debugger is active!
 * Debugger PIN: 342-159-773
Traceback (most recent call last):
  File "MountGod.py", line 1, in <module>
    import discord
ModuleNotFoundError: No module named 'discord'
Traceback (most recent call last):
  File "MountGod.py", line 8, in <module>
    from python.DefaultReaction import LearnReaction, ReturnReaction
  File "/home/orikami/CaseStudy2/MountGod/python/DefaultReaction.py", line 3, in <module>
    import Levenshtein
ModuleNotFoundError: No module named 'Levenshtein'
202.231.44.130 - - [02/Dec/2021 09:05:01] "GET / HTTP/1.1" 500 -
Traceback (most recent call last):
  File "/home/orikami/.local/lib/python3.7/site-packages/flask/app.py", line 2091, in __call__
    return self.wsgi_app(environ, start_response)
  File "/home/orikami/.local/lib/python3.7/site-packages/flask/app.py", line 2076, in wsgi_app
    response = self.handle_exception(e)
  File "/home/orikami/.local/lib/python3.7/site-packages/flask/app.py", line 2073, in wsgi_app
    response = self.full_dispatch_request()
  File "/home/orikami/.local/lib/python3.7/site-packages/flask/app.py", line 1518, in full_dispatch_request
    rv = self.handle_user_exception(e)
  File "/home/orikami/.local/lib/python3.7/site-packages/flask/app.py", line 1516, in full_dispatch_request
    rv = self.dispatch_request()
  File "/home/orikami/.local/lib/python3.7/site-packages/flask/app.py", line 1502, in dispatch_request
    return self.ensure_sync(self.view_functions[rule.endpoint])(**req.view_args)
  File "/home/orikami/CaseStudy2/MountGod/AIReplyAPI.py", line 11, in AIReplyAPI
    message = request.args.get("message").rstrip().replace("？", "?")
AttributeError: 'NoneType' object has no attribute 'rstrip'
202.231.44.130 - - [02/Dec/2021 09:05:01] "GET /?__debugger__=yes&cmd=resource&f=debugger.js HTTP/1.1" 200 -
202.231.44.130 - - [02/Dec/2021 09:05:01] "GET /?__debugger__=yes&cmd=resource&f=style.css HTTP/1.1" 200 -
202.231.44.130 - - [02/Dec/2021 09:05:01] "GET /?__debugger__=yes&cmd=resource&f=console.png HTTP/1.1" 200 -
202.231.44.130 - - [02/Dec/2021 09:05:02] "GET /?__debugger__=yes&cmd=resource&f=ubuntu.ttf HTTP/1.1" 200 -
202.231.44.130 - - [02/Dec/2021 09:05:02] "GET /?__debugger__=yes&cmd=resource&f=console.png HTTP/1.1" 200 -
202.231.44.130 - - [02/Dec/2021 09:05:33] "GET /?message=どう？ HTTP/1.1" 500 -
Traceback (most recent call last):
  File "/home/orikami/.local/lib/python3.7/site-packages/flask/app.py", line 2091, in __call__
    return self.wsgi_app(environ, start_response)
  File "/home/orikami/.local/lib/python3.7/site-packages/flask/app.py", line 2076, in wsgi_app
    response = self.handle_exception(e)
  File "/home/orikami/.local/lib/python3.7/site-packages/flask/app.py", line 2073, in wsgi_app
    response = self.full_dispatch_request()
  File "/home/orikami/.local/lib/python3.7/site-packages/flask/app.py", line 1518, in full_dispatch_request
    rv = self.handle_user_exception(e)
  File "/home/orikami/.local/lib/python3.7/site-packages/flask/app.py", line 1516, in full_dispatch_request
    rv = self.dispatch_request()
  File "/home/orikami/.local/lib/python3.7/site-packages/flask/app.py", line 1502, in dispatch_request
    return self.ensure_sync(self.view_functions[rule.endpoint])(**req.view_args)
  File "/home/orikami/CaseStudy2/MountGod/AIReplyAPI.py", line 27, in AIReplyAPI
    return jsonify({output+" ( %.5f [sec] )" % (time.time() - startTime)})
  File "/home/orikami/.local/lib/python3.7/site-packages/flask/json/__init__.py", line 355, in jsonify
    f"{dumps(data, indent=indent, separators=separators)}\n",
  File "/home/orikami/.local/lib/python3.7/site-packages/flask/json/__init__.py", line 133, in dumps
    rv = _json.dumps(obj, **kwargs)
  File "/usr/local/lib/python3.7/json/__init__.py", line 238, in dumps
    **kw).encode(obj)
  File "/usr/local/lib/python3.7/json/encoder.py", line 201, in encode
    chunks = list(chunks)
  File "/usr/local/lib/python3.7/json/encoder.py", line 438, in _iterencode
    o = _default(o)
  File "/home/orikami/.local/lib/python3.7/site-packages/flask/json/__init__.py", line 57, in default
    return super().default(o)
  File "/usr/local/lib/python3.7/json/encoder.py", line 179, in default
    raise TypeError(f'Object of type {o.__class__.__name__} '
TypeError: Object of type set is not JSON serializable
202.231.44.130 - - [02/Dec/2021 09:05:33] "GET /?__debugger__=yes&cmd=resource&f=style.css HTTP/1.1" 200 -
202.231.44.130 - - [02/Dec/2021 09:05:33] "GET /?__debugger__=yes&cmd=resource&f=debugger.js HTTP/1.1" 200 -
202.231.44.130 - - [02/Dec/2021 09:05:34] "GET /?__debugger__=yes&cmd=resource&f=console.png HTTP/1.1" 200 -
202.231.44.130 - - [02/Dec/2021 09:05:34] "GET /?__debugger__=yes&cmd=resource&f=ubuntu.ttf HTTP/1.1" 200 -
=======
Ignoring exception in on_message
Traceback (most recent call last):
  File "/usr/local/lib/python3.9/site-packages/urllib3/connection.py", line 174, in _new_conn
    conn = connection.create_connection(
  File "/usr/local/lib/python3.9/site-packages/urllib3/util/connection.py", line 96, in create_connection
    raise err
  File "/usr/local/lib/python3.9/site-packages/urllib3/util/connection.py", line 86, in create_connection
    sock.connect(sa)
ConnectionRefusedError: [Errno 111] Connection refused

During handling of the above exception, another exception occurred:

Traceback (most recent call last):
  File "/usr/local/lib/python3.9/site-packages/urllib3/connectionpool.py", line 699, in urlopen
    httplib_response = self._make_request(
  File "/usr/local/lib/python3.9/site-packages/urllib3/connectionpool.py", line 394, in _make_request
    conn.request(method, url, **httplib_request_kw)
  File "/usr/local/lib/python3.9/site-packages/urllib3/connection.py", line 239, in request
    super(HTTPConnection, self).request(method, url, body=body, headers=headers)
  File "/usr/local/lib/python3.9/http/client.py", line 1257, in request
    self._send_request(method, url, body, headers, encode_chunked)
  File "/usr/local/lib/python3.9/http/client.py", line 1303, in _send_request
    self.endheaders(body, encode_chunked=encode_chunked)
  File "/usr/local/lib/python3.9/http/client.py", line 1252, in endheaders
    self._send_output(message_body, encode_chunked=encode_chunked)
  File "/usr/local/lib/python3.9/http/client.py", line 1012, in _send_output
    self.send(msg)
  File "/usr/local/lib/python3.9/http/client.py", line 952, in send
    self.connect()
  File "/usr/local/lib/python3.9/site-packages/urllib3/connection.py", line 205, in connect
    conn = self._new_conn()
  File "/usr/local/lib/python3.9/site-packages/urllib3/connection.py", line 186, in _new_conn
    raise NewConnectionError(
urllib3.exceptions.NewConnectionError: <urllib3.connection.HTTPConnection object at 0xb32b3be0>: Failed to establish a new connection: [Errno 111] Connection refused

During handling of the above exception, another exception occurred:

Traceback (most recent call last):
  File "/usr/local/lib/python3.9/site-packages/requests/adapters.py", line 439, in send
    resp = conn.urlopen(
  File "/usr/local/lib/python3.9/site-packages/urllib3/connectionpool.py", line 755, in urlopen
    retries = retries.increment(
  File "/usr/local/lib/python3.9/site-packages/urllib3/util/retry.py", line 574, in increment
    raise MaxRetryError(_pool, url, error or ResponseError(cause))
urllib3.exceptions.MaxRetryError: HTTPConnectionPool(host='localhost', port=51401): Max retries exceeded with url: /?message=AI%20%E5%85%AC%E6%98%8E%E5%85%9A (Caused by NewConnectionError('<urllib3.connection.HTTPConnection object at 0xb32b3be0>: Failed to establish a new connection: [Errno 111] Connection refused'))

During handling of the above exception, another exception occurred:

Traceback (most recent call last):
  File "/usr/local/lib/python3.9/site-packages/discord/client.py", line 343, in _run_event
    await coro(*args, **kwargs)
  File "/home/orikami/MountGod/MountGod.py", line 60, in on_message
    returnValue = AIReply(message.content)
  File "/home/orikami/MountGod/python/AIReply.py", line 7, in AIReply
    returnValue = requests.get(
  File "/usr/local/lib/python3.9/site-packages/requests/api.py", line 75, in get
    return request('get', url, params=params, **kwargs)
  File "/usr/local/lib/python3.9/site-packages/requests/api.py", line 61, in request
    return session.request(method=method, url=url, **kwargs)
  File "/usr/local/lib/python3.9/site-packages/requests/sessions.py", line 542, in request
    resp = self.send(prep, **send_kwargs)
  File "/usr/local/lib/python3.9/site-packages/requests/sessions.py", line 655, in send
    r = adapter.send(request, **kwargs)
  File "/usr/local/lib/python3.9/site-packages/requests/adapters.py", line 516, in send
    raise ConnectionError(e, request=request)
requests.exceptions.ConnectionError: HTTPConnectionPool(host='localhost', port=51401): Max retries exceeded with url: /?message=AI%20%E5%85%AC%E6%98%8E%E5%85%9A (Caused by NewConnectionError('<urllib3.connection.HTTPConnection object at 0xb32b3be0>: Failed to establish a new connection: [Errno 111] Connection refused'))
Ignoring exception in on_message
Traceback (most recent call last):
  File "/usr/local/lib/python3.9/site-packages/urllib3/connection.py", line 174, in _new_conn
    conn = connection.create_connection(
  File "/usr/local/lib/python3.9/site-packages/urllib3/util/connection.py", line 96, in create_connection
    raise err
  File "/usr/local/lib/python3.9/site-packages/urllib3/util/connection.py", line 86, in create_connection
    sock.connect(sa)
ConnectionRefusedError: [Errno 111] Connection refused

During handling of the above exception, another exception occurred:

Traceback (most recent call last):
  File "/usr/local/lib/python3.9/site-packages/urllib3/connectionpool.py", line 699, in urlopen
    httplib_response = self._make_request(
  File "/usr/local/lib/python3.9/site-packages/urllib3/connectionpool.py", line 394, in _make_request
    conn.request(method, url, **httplib_request_kw)
  File "/usr/local/lib/python3.9/site-packages/urllib3/connection.py", line 239, in request
    super(HTTPConnection, self).request(method, url, body=body, headers=headers)
  File "/usr/local/lib/python3.9/http/client.py", line 1257, in request
    self._send_request(method, url, body, headers, encode_chunked)
  File "/usr/local/lib/python3.9/http/client.py", line 1303, in _send_request
    self.endheaders(body, encode_chunked=encode_chunked)
  File "/usr/local/lib/python3.9/http/client.py", line 1252, in endheaders
    self._send_output(message_body, encode_chunked=encode_chunked)
  File "/usr/local/lib/python3.9/http/client.py", line 1012, in _send_output
    self.send(msg)
  File "/usr/local/lib/python3.9/http/client.py", line 952, in send
    self.connect()
  File "/usr/local/lib/python3.9/site-packages/urllib3/connection.py", line 205, in connect
    conn = self._new_conn()
  File "/usr/local/lib/python3.9/site-packages/urllib3/connection.py", line 186, in _new_conn
    raise NewConnectionError(
urllib3.exceptions.NewConnectionError: <urllib3.connection.HTTPConnection object at 0xb2a4c3e8>: Failed to establish a new connection: [Errno 111] Connection refused

During handling of the above exception, another exception occurred:

Traceback (most recent call last):
  File "/usr/local/lib/python3.9/site-packages/requests/adapters.py", line 439, in send
    resp = conn.urlopen(
  File "/usr/local/lib/python3.9/site-packages/urllib3/connectionpool.py", line 755, in urlopen
    retries = retries.increment(
  File "/usr/local/lib/python3.9/site-packages/urllib3/util/retry.py", line 574, in increment
    raise MaxRetryError(_pool, url, error or ResponseError(cause))
urllib3.exceptions.MaxRetryError: HTTPConnectionPool(host='localhost', port=51401): Max retries exceeded with url: /?message=AI%20%E5%85%AC%E6%98%8E%E5%85%9A (Caused by NewConnectionError('<urllib3.connection.HTTPConnection object at 0xb2a4c3e8>: Failed to establish a new connection: [Errno 111] Connection refused'))

During handling of the above exception, another exception occurred:

Traceback (most recent call last):
  File "/usr/local/lib/python3.9/site-packages/discord/client.py", line 343, in _run_event
    await coro(*args, **kwargs)
  File "/home/orikami/MountGod/MountGod.py", line 60, in on_message
    returnValue = AIReply(message.content)
  File "/home/orikami/MountGod/python/AIReply.py", line 7, in AIReply
    returnValue = requests.get(
  File "/usr/local/lib/python3.9/site-packages/requests/api.py", line 75, in get
    return request('get', url, params=params, **kwargs)
  File "/usr/local/lib/python3.9/site-packages/requests/api.py", line 61, in request
    return session.request(method=method, url=url, **kwargs)
  File "/usr/local/lib/python3.9/site-packages/requests/sessions.py", line 542, in request
    resp = self.send(prep, **send_kwargs)
  File "/usr/local/lib/python3.9/site-packages/requests/sessions.py", line 655, in send
    r = adapter.send(request, **kwargs)
  File "/usr/local/lib/python3.9/site-packages/requests/adapters.py", line 516, in send
    raise ConnectionError(e, request=request)
requests.exceptions.ConnectionError: HTTPConnectionPool(host='localhost', port=51401): Max retries exceeded with url: /?message=AI%20%E5%85%AC%E6%98%8E%E5%85%9A (Caused by NewConnectionError('<urllib3.connection.HTTPConnection object at 0xb2a4c3e8>: Failed to establish a new connection: [Errno 111] Connection refused'))
>>>>>>> 4c1126d753ee6af74de98ed5aea5ff08f94ed658
2021-12-09 15:43:08.080096: W tensorflow/stream_executor/platform/default/dso_loader.cc:64] Could not load dynamic library 'libcudart.so.11.0'; dlerror: libcudart.so.11.0: cannot open shared object file: No such file or directory
2021-12-09 15:43:08.080139: I tensorflow/stream_executor/cuda/cudart_stub.cc:29] Ignore above cudart dlerror if you do not have a GPU set up on your machine.
 * Serving Flask app 'AIReplyAPI' (lazy loading)
 * Environment: production
   WARNING: This is a development server. Do not use it in a production deployment.
   Use a production WSGI server instead.
 * Debug mode: on
Traceback (most recent call last):
  File "AIReplyAPI.py", line 31, in <module>
    app.run(host="0.0.0.0", port=443, debug=True)
  File "/home/orikami/.local/lib/python3.7/site-packages/flask/app.py", line 920, in run
    run_simple(t.cast(str, host), port, self, **options)
  File "/home/orikami/.local/lib/python3.7/site-packages/werkzeug/serving.py", line 984, in run_simple
    s.bind(server_address)
PermissionError: [Errno 13] Permission denied
2021-12-09 15:44:04.901350: W tensorflow/stream_executor/platform/default/dso_loader.cc:64] Could not load dynamic library 'libcudart.so.11.0'; dlerror: libcudart.so.11.0: cannot open shared object file: No such file or directory
2021-12-09 15:44:04.901392: I tensorflow/stream_executor/cuda/cudart_stub.cc:29] Ignore above cudart dlerror if you do not have a GPU set up on your machine.
 * Serving Flask app 'AIReplyAPI' (lazy loading)
 * Environment: production
   WARNING: This is a development server. Do not use it in a production deployment.
   Use a production WSGI server instead.
 * Debug mode: on
Traceback (most recent call last):
  File "AIReplyAPI.py", line 31, in <module>
    app.run(host="0.0.0.0", port=443, debug=True)
  File "/home/orikami/.local/lib/python3.7/site-packages/flask/app.py", line 920, in run
    run_simple(t.cast(str, host), port, self, **options)
  File "/home/orikami/.local/lib/python3.7/site-packages/werkzeug/serving.py", line 984, in run_simple
    s.bind(server_address)
PermissionError: [Errno 13] Permission denied
