Ignoring exception in on_message
Traceback (most recent call last):
  File "/home/orikami/MountGod/python/AIReply.py", line 10, in AIReply
    subprocess.call("ssh orikami@202.231.44.104")
  File "/usr/local/lib/python3.9/subprocess.py", line 349, in call
    with Popen(*popenargs, **kwargs) as p:
  File "/usr/local/lib/python3.9/subprocess.py", line 951, in __init__
    self._execute_child(args, executable, preexec_fn, close_fds,
  File "/usr/local/lib/python3.9/subprocess.py", line 1821, in _execute_child
    raise child_exception_type(errno_num, err_msg, err_filename)
FileNotFoundError: [Errno 2] No such file or directory: 'ssh orikami@202.231.44.104'

During handling of the above exception, another exception occurred:

Traceback (most recent call last):
  File "/usr/local/lib/python3.9/site-packages/discord/client.py", line 343, in _run_event
    await coro(*args, **kwargs)
  File "/home/orikami/MountGod/MountGod.py", line 44, in on_message
    returnValue = AIReply(message.content)
  File "/home/orikami/MountGod/python/AIReply.py", line 14, in AIReply
    return "エラー：" + e.args[0]
TypeError: can only concatenate str (not "int") to str
I'm on ready...
